<?xml version="1.0" encoding="utf-8"?>
  name="linkerhand_l20lite_left.urdf">
  <link
    name="hand_base_link">
    <inertial>
      <origin
        xyz="-0.00378861347432373 0.000820204450131895 0.0805686615689543"
        rpy="0 0 0" />
      <mass
        value="0.103652479414672" />
      <inertia
        ixx="0.000193076183440551"
        ixy="1.28622350247875E-06"
        ixz="-2.06064564153793E-07"
        iyy="0.000129262885172737"
        iyz="-2.33887125894354E-06"
        izz="7.7154522927273E-05" />
    </inertial>
    <visual>
      <origin
        xyz="0 0 0"
        rpy="0 0 0" />
      <geometry>
        <mesh
          filename="meshes/hand_base_link.STL" />
      </geometry>
      <material
        name="">
        <color
          rgba="0.59 0.66 0.68 1" />
      </material>
    </visual>
    <collision>
      <origin
        xyz="0 0 0"
        rpy="0 0 0" />
      <geometry>
        <mesh
          filename="meshes/hand_base_link.STL" />
      </geometry>
    </collision>
  </link>
  <link
    name="thumb_metacarpals_base1">
    <inertial>
      <origin
        xyz="0.0284841419451473 0.0032328053117659 1.27102541975441E-05"
        rpy="0 0 0" />
      <mass
        value="0.00840514828448049" />
      <inertia
        ixx="1.40225690783513E-06"
        ixy="1.196162690714E-07"
        ixz="7.34629714950971E-09"
        iyy="9.92532738625187E-07"
        iyz="-4.63982709938509E-08"
        izz="7.25924523731736E-07" />
    </inertial>
    <visual>
      <origin
        xyz="0 0 0"
        rpy="0 0 0" />
      <geometry>
        <mesh
          filename="meshes/thumb_metacarpals_base1.STL" />
      </geometry>
      <material
        name="">
        <color
          rgba="0.59 0.66 0.68 1" />
      </material>
    </visual>
    <collision>
      <origin
        xyz="0 0 0"
        rpy="0 0 0" />
      <geometry>
        <mesh
          filename="meshes/thumb_metacarpals_base1.STL" />
      </geometry>
    </collision>
  </link>
  <joint
    name="thumb_cmc_roll"
    type="revolute">
    <origin
      xyz="-0.013419 -0.012551 0.060602"
      rpy="0 0 0" />
    <parent
      link="hand_base_link" />
    <child
      link="thumb_metacarpals_base1" />
    <axis
      xyz="-0.99996 0 -0.0087265" />
    <limit
      lower="0"
      upper="1.03"
      effort="4.8"
      velocity="1" />
  </joint>
  <link
    name="thumb_metacarpals_base2">
    <inertial>
      <origin
        xyz="0.00149333647480262 -0.00615813217507052 -0.000273768129351912"
        rpy="0 0 0" />
      <mass
        value="0.00244725656099355" />
      <inertia
        ixx="1.15757169903916E-07"
        ixy="-4.50060051446398E-09"
        ixz="-9.19744539328016E-10"
        iyy="9.88121769947347E-08"
        iyz="3.81969206030993E-09"
        izz="6.88506418885536E-08" />
    </inertial>
    <visual>
      <origin
        xyz="0 0 0"
        rpy="0 0 0" />
      <geometry>
        <mesh
          filename="meshes/thumb_metacarpals_base2.STL" />
      </geometry>
      <material
        name="">
        <color
          rgba="0.59 0.66 0.68 1" />
      </material>
    </visual>
    <collision>
      <origin
        xyz="0 0 0"
        rpy="0 0 0" />
      <geometry>
        <mesh
          filename="meshes/thumb_metacarpals_base2.STL" />
      </geometry>
    </collision>
  </link>
  <joint
    name="thumb_cmc_yaw"
    type="revolute">
    <origin
      xyz="0.035797 0.00065879 0.00045944"
      rpy="0.13232 -0.0087266 0" />
    <parent
      link="thumb_metacarpals_base1" />
    <child
      link="thumb_metacarpals_base2" />
    <axis
      xyz="0 0.087156 0.99619" />
    <limit
      lower="0"
      upper="1.40"
      effort="4.8"
      velocity="1" />
  </joint>
  <link
    name="thumb_metacarpals">
    <inertial>
      <origin
        xyz="0.00183663729904029 3.46162460989133E-06 0.026990412201572"
        rpy="0 0 0" />
      <mass
        value="0.0152011788694593" />
      <inertia
        ixx="2.95369587925714E-06"
        ixy="4.74536745194236E-11"
        ixz="-1.58087239939667E-07"
        iyy="3.84770419198789E-06"
        iyz="4.13672896569864E-10"
        izz="1.32008560539723E-06" />
    </inertial>
    <visual>
      <origin
        xyz="0 0 0"
        rpy="0 0 0" />
      <geometry>
        <mesh
          filename="meshes/thumb_metacarpals.STL" />
      </geometry>
      <material
        name="">
        <color
          rgba="0.59 0.66 0.68 1" />
      </material>
    </visual>
    <collision>
      <origin
        xyz="0 0 0"
        rpy="0 0 0" />
      <geometry>
        <mesh
          filename="meshes/thumb_metacarpals.STL" />
      </geometry>
    </collision>
  </link>
  <joint
    name="thumb_cmc_pitch"
    type="revolute">
    <origin
      xyz="0.0036974 -0.015398 -0.0019891"
      rpy="0 -0.9163 1.8064" />
    <parent
      link="thumb_metacarpals_base2" />
    <child
      link="thumb_metacarpals" />
    <axis
      xyz="0 1 0" />
    <limit
      lower="0"
      upper="0.52"
      effort="4.8"
      velocity="1" />
  </joint>
  <link
    name="thumb_proximal">
    <inertial>
      <origin
        xyz="0.00159260267405223 4.28988976902342E-06 0.0151572309111939"
        rpy="0 0 0" />
      <mass
        value="0.00662225085289633" />
      <inertia
        ixx="1.01526328949763E-06"
        ixy="-7.87460584199835E-12"
        ixz="-4.4224308859969E-08"
        iyy="9.10425089721739E-07"
        iyz="2.81833762972893E-11"
        izz="4.47462917464685E-07" />
    </inertial>
    <visual>
      <origin
        xyz="0 0 0"
        rpy="0 0 0" />
      <geometry>
        <mesh
          filename="meshes/thumb_proximal.STL" />
      </geometry>
      <material
        name="">
        <color
          rgba="0.59 0.66 0.68 1" />
      </material>
    </visual>
    <collision>
      <origin
        xyz="0 0 0"
        rpy="0 0 0" />
      <geometry>
        <mesh
          filename="meshes/thumb_proximal.STL" />
      </geometry>
    </collision>
  </link>
  <joint
    name="thumb_mcp"
    type="revolute">
    <origin
      xyz="0.0061722 0 0.047968"
      rpy="0 0 0" />
    <parent
      link="thumb_metacarpals" />
    <child
      link="thumb_proximal" />
    <axis
      xyz="0 1 0" />
    <limit
      lower="0"
      upper="0.72"
      effort="3.7"
      velocity="1" />
    <mimic
      joint="thumb_cmc_pitch"
      multiplier="1.38"
      offset="0" />
  </joint>
  <link
    name="thumb_distal">
    <inertial>
      <origin
        xyz="-0.00138833978915306 -1.92768110708619E-06 0.0115764513296314"
        rpy="0 0 0" />
      <mass
        value="0.00512798334000111" />
      <inertia
        ixx="3.30808161248092E-07"
        ixy="-3.43833611720834E-10"
        ixz="-1.04696624534012E-07"
        iyy="3.2363078244428E-07"
        iyz="-1.18697138701936E-10"
        izz="2.48875198442135E-07" />
    </inertial>
    <visual>
      <origin
        xyz="0 0 0"
        rpy="0 0 0" />
      <geometry>
        <mesh
          filename="meshes/thumb_distal.STL" />
      </geometry>
      <material
        name="">
        <color
          rgba="0.59 0.66 0.68 1" />
      </material>
    </visual>
    <collision>
      <origin
        xyz="0 0 0"
        rpy="0 0 0" />
      <geometry>
        <mesh
          filename="meshes/thumb_distal.STL" />
      </geometry>
    </collision>
  </link>
  <joint
    name="thumb_ip"
    type="revolute">
    <origin
      xyz="-0.00017064 0 0.038665"
      rpy="0 0 0" />
    <parent
      link="thumb_proximal" />
    <child
      link="thumb_distal" />
    <axis
      xyz="0 1 0" />
    <limit
      lower="0"
      upper="0.78"
      effort="3.36"
      velocity="1" />
    <mimic
      joint="thumb_cmc_pitch"
      multiplier="1.49"
      offset="0" />
  </joint>
  <link
    name="index_metacarpals">
    <inertial>
      <origin
        xyz="-0.00143091454702933 2.56878017135254E-07 0.0107040528609869"
        rpy="0 0 0" />
      <mass
        value="0.0038877126435198" />
      <inertia
        ixx="1.87149599832498E-07"
        ixy="3.67335498441413E-11"
        ixz="1.3415127653338E-08"
        iyy="2.75278147668716E-07"
        iyz="2.44762951204078E-11"
        izz="2.06866317113344E-07" />
    </inertial>
    <visual>
      <origin
        xyz="0 0 0"
        rpy="0 0 0" />
      <geometry>
        <mesh
          filename="meshes/index_metacarpals.STL" />
      </geometry>
      <material
        name="">
        <color
          rgba="0.59 0.66 0.68 1" />
      </material>
    </visual>
    <collision>
      <origin
        xyz="0 0 0"
        rpy="0 0 0" />
      <geometry>
        <mesh
          filename="meshes/index_metacarpals.STL" />
      </geometry>
    </collision>
  </link>
  <joint
    name="index_mcp_roll"
    type="revolute">
    <origin
      xyz="-0.0021643 -0.026654 0.13253"
      rpy="0.027927 -0.0087198 -0.00024358" />
    <parent
      link="hand_base_link" />
    <child
      link="index_metacarpals" />
    <axis
      xyz="1 0.00024367 0" />
    <limit
      lower="0"
      upper="0.19"
      effort="4.29"
      velocity="1" />
  </joint>
  <link
    name="index_proximal">
    <inertial>
      <origin
        xyz="-0.00122347616770057 -2.04121170566118E-06 0.0182409893195748"
        rpy="0 0 0" />
      <mass
        value="0.00316246584579941" />
      <inertia
        ixx="3.57135128024094E-07"
        ixy="1.42036124901073E-11"
        ixz="-4.14209968733606E-08"
        iyy="3.51905870436209E-07"
        iyz="-1.08557233942923E-10"
        izz="1.40872561400322E-07" />
    </inertial>
    <visual>
      <origin
        xyz="0 0 0"
        rpy="0 0 0" />
      <geometry>
        <mesh
          filename="meshes/index_proximal.STL" />
      </geometry>
      <material
        name="">
        <color
          rgba="0.59 0.66 0.68 1" />
      </material>
    </visual>
    <collision>
      <origin
        xyz="0 0 0"
        rpy="0 0 0" />
      <geometry>
        <mesh
          filename="meshes/index_proximal.STL" />
      </geometry>
    </collision>
  </link>
  <joint
    name="index_mcp_pitch"
    type="revolute">
    <origin
      xyz="0.0022097 0 0.015275"
      rpy="0 0 0.00024367" />
    <parent
      link="index_metacarpals" />
    <child
      link="index_proximal" />
    <axis
      xyz="0 1 0" />
    <limit
      lower="0"
      upper="1.36"
      effort="4.8"
      velocity="1" />
  </joint>
  <link
    name="index_middle">
    <inertial>
      <origin
        xyz="-0.00250309203564306 2.18945385091485E-06 0.0110397390913486"
        rpy="0 0 0" />
      <mass
        value="0.00283043921422803" />
      <inertia
        ixx="2.61037133593912E-07"
        ixy="5.76197451786318E-11"
        ixz="-4.0011060525121E-08"
        iyy="2.33077518995487E-07"
        iyz="-2.86979503467821E-11"
        izz="1.26543797445814E-07" />
    </inertial>
    <visual>
      <origin
        xyz="0 0 0"
        rpy="0 0 0" />
      <geometry>
        <mesh
          filename="meshes/index_middle.STL" />
      </geometry>
      <material
        name="">
        <color
          rgba="0.59 0.66 0.68 1" />
      </material>
    </visual>
    <collision>
      <origin
        xyz="0 0 0"
        rpy="0 0 0" />
      <geometry>
        <mesh
          filename="meshes/index_middle.STL" />
      </geometry>
    </collision>
  </link>
  <joint
    name="index_pip"
    type="revolute">
    <origin
      xyz="-0.0010697 0 0.035634"
      rpy="0 0 0" />
    <parent
      link="index_proximal" />
    <child
      link="index_middle" />
    <axis
      xyz="0 1 0" />
    <limit
      lower="0"
      upper="1.78"
      effort="3.7"
      velocity="1" />
    <mimic
      joint="index_mcp_pitch"
      multiplier="1.3"
      offset="0" />
  </joint>
  <link
    name="index_distal">
    <inertial>
      <origin
        xyz="-0.000604509916724614 -4.77400032578013E-06 0.0121511111849248"
        rpy="0 0 0" />
      <mass
        value="0.0031445375098231" />
      <inertia
        ixx="1.64070673729839E-07"
        ixy="1.88963511473794E-11"
        ixz="-4.27776869144244E-08"
        iyy="1.48362830813358E-07"
        iyz="-1.9734013143508E-10"
        izz="9.7804088657243E-08" />
    </inertial>
    <visual>
      <origin
        xyz="0 0 0"
        rpy="0 0 0" />
      <geometry>
        <mesh
          filename="meshes/index_distal.STL" />
      </geometry>
      <material
        name="">
        <color
          rgba="0.59 0.66 0.68 1" />
      </material>
    </visual>
    <collision>
      <origin
        xyz="0 0 0"
        rpy="0 0 0" />
      <geometry>
        <mesh
          filename="meshes/index_distal.STL" />
      </geometry>
    </collision>
  </link>
  <joint
    name="index_dip"
    type="revolute">
    <origin
      xyz="-0.0052444 0 0.025711"
      rpy="0 0 0" />
    <parent
      link="index_middle" />
    <child
      link="index_distal" />
    <axis
      xyz="0 1 0" />
    <limit
      lower="0"
      upper="0.62"
      effort="10.43"
      velocity="1" />
    <mimic
      joint="index_mcp_pitch"
      multiplier="0.46"
      offset="0" />
  </joint>
  <link
    name="middle_proximal">
    <inertial>
      <origin
        xyz="-0.00123185150819907 -2.04476498746886E-06 0.0182404193627525"
        rpy="0 0 0" />
      <mass
        value="0.00316246719662224" />
      <inertia
        ixx="3.57097075648345E-07"
        ixy="1.43002807788619E-11"
        ixz="-4.15201646947523E-08"
        iyy="3.51905920397223E-07"
        iyz="-1.08488557665733E-10"
        izz="1.4091067749978E-07" />
    </inertial>
    <visual>
      <origin
        xyz="0 0 0"
        rpy="0 0 0" />
      <geometry>
        <mesh
          filename="meshes/middle_proximal.STL" />
      </geometry>
      <material
        name="">
        <color
          rgba="0.59 0.66 0.68 1" />
      </material>
    </visual>
    <collision>
      <origin
        xyz="0 0 0"
        rpy="0 0 0" />
      <geometry>
        <mesh
          filename="meshes/middle_proximal.STL" />
      </geometry>
    </collision>
  </link>
  <joint
    name="middle_mcp_pitch"
    type="revolute">
    <origin
      xyz="-0.0021316 -0.0076542 0.15281"
      rpy="0 -0.0087266 0" />
    <parent
      link="hand_base_link" />
    <child
      link="middle_proximal" />
    <axis
      xyz="0 1 0" />
    <limit
      lower="0"
      upper="1.36"
      effort="4.8"
      velocity="1" />
  </joint>
  <link
    name="middle_middle">
    <inertial>
      <origin
        xyz="-0.00252079729924576 2.18964489481777E-06 0.0110357094277332"
        rpy="0 0 0" />
      <mass
        value="0.00283043921858529" />
      <inertia
        ixx="2.60908423355366E-07"
        ixy="5.76720293661014E-11"
        ixz="-4.02265908644236E-08"
        iyy="2.33077520740401E-07"
        iyz="-2.86057758459882E-11"
        izz="1.26672514044425E-07" />
    </inertial>
    <visual>
      <origin
        xyz="0 0 0"
        rpy="0 0 0" />
      <geometry>
        <mesh
          filename="meshes/middle_middle.STL" />
      </geometry>
      <material
        name="">
        <color
          rgba="0.59 0.66 0.68 1" />
      </material>
    </visual>
    <collision>
      <origin
        xyz="0 0 0"
        rpy="0 0 0" />
      <geometry>
        <mesh
          filename="meshes/middle_middle.STL" />
      </geometry>
    </collision>
  </link>
  <joint
    name="middle_pip"
    type="revolute">
    <origin
      xyz="-0.0010861 0 0.035634"
      rpy="0 0 0" />
    <parent
      link="middle_proximal" />
    <child
      link="middle_middle" />
    <axis
      xyz="0 1 0" />
    <limit
      lower="0"
      upper="1.78"
      effort="3.7"
      velocity="1" />
    <mimic
      joint="middle_mcp_pitch"
      multiplier="1.3"
      offset="0" />
  </joint>
  <link
    name="middle_distal">
    <inertial>
      <origin
        xyz="-0.000622397825955366 -4.75569749899818E-06 0.012150171418504"
        rpy="0 0 0" />
      <mass
        value="0.00314452092964384" />
      <inertia
        ixx="1.63942838563309E-07"
        ixy="1.9526841627913E-11"
        ixz="-4.28753645610842E-08"
        iyy="1.48361296215111E-07"
        iyz="-1.96949597957508E-10"
        izz="9.7929884595885E-08" />
    </inertial>
    <visual>
      <origin
        xyz="0 0 0"
        rpy="0 0 0" />
      <geometry>
        <mesh
          filename="meshes/middle_distal.STL" />
      </geometry>
      <material
        name="">
        <color
          rgba="0.59 0.66 0.68 1" />
      </material>
    </visual>
    <collision>
      <origin
        xyz="0 0 0"
        rpy="0 0 0" />
      <geometry>
        <mesh
          filename="meshes/middle_distal.STL" />
      </geometry>
    </collision>
  </link>
  <joint
    name="middle_dip"
    type="revolute">
    <origin
      xyz="-0.0052857 0 0.025703"
      rpy="0 0 0" />
    <parent
      link="middle_middle" />
    <child
      link="middle_distal" />
    <axis
      xyz="0 1 0" />
    <limit
      lower="0"
      upper="0.62"
      effort="10.43"
      velocity="1" />
    <mimic
      joint="middle_mcp_pitch"
      multiplier="0.46"
      offset="0" />
  </joint>
  <link
    name="ring_metacarpals">
    <inertial>
      <origin
        xyz="-0.00143091448892014 6.05495226457808E-07 0.0107040523320813"
        rpy="0 0 0" />
      <mass
        value="0.00388771255966599" />
      <inertia
        ixx="1.87149578481638E-07"
        ixy="1.52642675041227E-11"
        ixz="1.34151349601248E-08"
        iyy="2.75278155094349E-07"
        iyz="2.12062463357117E-11"
        izz="2.06866318930306E-07" />
    </inertial>
    <visual>
      <origin
        xyz="0 0 0"
        rpy="0 0 0" />
      <geometry>
        <mesh
          filename="meshes/ring_metacarpals.STL" />
      </geometry>
      <material
        name="">
        <color
          rgba="0.59 0.66 0.68 1" />
      </material>
    </visual>
    <collision>
      <origin
        xyz="0 0 0"
        rpy="0 0 0" />
      <geometry>
        <mesh
          filename="meshes/ring_metacarpals.STL" />
      </geometry>
    </collision>
  </link>
  <joint
    name="ring_mcp_roll"
    type="revolute">
    <origin
      xyz="-0.0021643 0.011346 0.13253"
      rpy="-0.024435 -0.0087266 0" />
    <parent
      link="hand_base_link" />
    <child
      link="ring_metacarpals" />
    <axis
      xyz="-1 0 0" />
    <limit
      lower="0"
      upper="0.2"
      effort="4.29"
      velocity="1" />
  </joint>
  <link
    name="ring_proximal">
    <inertial>
      <origin
        xyz="-0.00122347652312429 -2.0423407393888E-06 0.0182409875332818"
        rpy="0 0 0" />
      <mass
        value="0.00316246660225829" />
      <inertia
        ixx="3.5713512847731E-07"
        ixy="1.42130904393983E-11"
        ixz="-4.14209983311065E-08"
        iyy="3.51905881089114E-07"
        iyz="-1.08576103054512E-10"
        izz="1.40872582931496E-07" />
    </inertial>
    <visual>
      <origin
        xyz="0 0 0"
        rpy="0 0 0" />
      <geometry>
        <mesh
          filename="meshes/ring_proximal.STL" />
      </geometry>
      <material
        name="">
        <color
          rgba="0.59 0.66 0.68 1" />
      </material>
    </visual>
    <collision>
      <origin
        xyz="0 0 0"
        rpy="0 0 0" />
      <geometry>
        <mesh
          filename="meshes/ring_proximal.STL" />
      </geometry>
    </collision>
  </link>
  <joint
    name="ring_mcp_pitch"
    type="revolute">
    <origin
      xyz="0.0022097 0 0.015275"
      rpy="0 0 0" />
    <parent
      link="ring_metacarpals" />
    <child
      link="ring_proximal" />
    <axis
      xyz="0 1 0" />
    <limit
      lower="0"
      upper="1.36"
      effort="4.8"
      velocity="1" />
  </joint>
  <link
    name="ring_middle">
    <inertial>
      <origin
        xyz="-0.00250309189885196 2.18959036171751E-06 0.0110397385966097"
        rpy="0 0 0" />
      <mass
        value="0.00283043920090097" />
      <inertia
        ixx="2.61037130501287E-07"
        ixy="5.76216047828233E-11"
        ixz="-4.00110582573436E-08"
        iyy="2.33077521207674E-07"
        iyz="-2.86985395311388E-11"
        izz="1.26543807918808E-07" />
    </inertial>
    <visual>
      <origin
        xyz="0 0 0"
        rpy="0 0 0" />
      <geometry>
        <mesh
          filename="meshes/ring_middle.STL" />
      </geometry>
      <material
        name="">
        <color
          rgba="0.59 0.66 0.68 1" />
      </material>
    </visual>
    <collision>
      <origin
        xyz="0 0 0"
        rpy="0 0 0" />
      <geometry>
        <mesh
          filename="meshes/ring_middle.STL" />
      </geometry>
    </collision>
  </link>
  <joint
    name="ring_pip"
    type="revolute">
    <origin
      xyz="-0.0010697 0 0.035634"
      rpy="0 0 0" />
    <parent
      link="ring_proximal" />
    <child
      link="ring_middle" />
    <axis
      xyz="0 1 0" />
    <limit
      lower="0"
      upper="1.78"
      effort="3.7"
      velocity="1" />
    <mimic
      joint="ring_mcp_pitch"
      multiplier="1.3"
      offset="0" />
  </joint>
  <link
    name="ring_distal">
    <inertial>
      <origin
        xyz="-0.000604497650389674 -4.73100652065295E-06 0.012151126431567"
        rpy="0 0 0" />
      <mass
        value="0.00314454943731604" />
      <inertia
        ixx="1.64071049652571E-07"
        ixy="1.94791513771428E-11"
        ixz="-4.27777374237679E-08"
        iyy="1.48363091013624E-07"
        iyz="-1.96468435398403E-10"
        izz="9.78042601257212E-08" />
    </inertial>
    <visual>
      <origin
        xyz="0 0 0"
        rpy="0 0 0" />
      <geometry>
        <mesh
          filename="meshes/ring_distal.STL" />
      </geometry>
      <material
        name="">
        <color
          rgba="0.59 0.66 0.68 1" />
      </material>
    </visual>
    <collision>
      <origin
        xyz="0 0 0"
        rpy="0 0 0" />
      <geometry>
        <mesh
          filename="meshes/ring_distal.STL" />
      </geometry>
    </collision>
  </link>
  <joint
    name="ring_dip"
    type="revolute">
    <origin
      xyz="-0.0052444 0 0.025711"
      rpy="0 0 0" />
    <parent
      link="ring_middle" />
    <child
      link="ring_distal" />
    <axis
      xyz="0 1 0" />
    <limit
      lower="0"
      upper="0.62"
      effort="10.43"
      velocity="1" />
    <mimic
      joint="ring_mcp_pitch"
      multiplier="0.46"
      offset="0" />
  </joint>
  <link
    name="pinky_metacarpals">
    <inertial>
      <origin
        xyz="-0.00143091630673887 6.05311374107798E-07 0.010704049929046"
        rpy="0 0 0" />
      <mass
        value="0.00388771229554929" />
      <inertia
        ixx="1.87149536268889E-07"
        ixy="1.52679681737727E-11"
        ixz="1.34151204706615E-08"
        iyy="2.75278106047772E-07"
        iyz="2.11967245454867E-11"
        izz="2.06866328803883E-07" />
    </inertial>
    <visual>
      <origin
        xyz="0 0 0"
        rpy="0 0 0" />
      <geometry>
        <mesh
          filename="meshes/pinky_metacarpals.STL" />
      </geometry>
      <material
        name="">
        <color
          rgba="0.59 0.66 0.68 1" />
      </material>
    </visual>
    <collision>
      <origin
        xyz="0 0 0"
        rpy="0 0 0" />
      <geometry>
        <mesh
          filename="meshes/pinky_metacarpals.STL" />
      </geometry>
    </collision>
  </link>
  <joint
    name="pinky_mcp_roll"
    type="revolute">
    <origin
      xyz="-0.00012074 0.030346 0.12755"
      rpy="-0.057596 -0.0087266 0" />
    <parent
      link="hand_base_link" />
    <child
      link="pinky_metacarpals" />
    <axis
      xyz="-1 0 0" />
    <limit
      lower="0"
      upper="0.3"
      effort="4.29"
      velocity="1" />
  </joint>
  <link
    name="pinky_proximal">
    <inertial>
      <origin
        xyz="-0.00122347805395697 -2.04329569369888E-06 0.0182409919418033"
        rpy="0 0 0" />
      <mass
        value="0.00316246781629033" />
      <inertia
        ixx="3.57135263144139E-07"
        ixy="1.42286998987323E-11"
        ixz="-4.14209901998364E-08"
        iyy="3.5190602349514E-07"
        iyz="-1.08636442666922E-10"
        izz="1.40872647811026E-07" />
    </inertial>
    <visual>
      <origin
        xyz="0 0 0"
        rpy="0 0 0" />
      <geometry>
        <mesh
          filename="meshes/pinky_proximal.STL" />
      </geometry>
      <material
        name="">
        <color
          rgba="0.59 0.66 0.68 1" />
      </material>
    </visual>
    <collision>
      <origin
        xyz="0 0 0"
        rpy="0 0 0" />
      <geometry>
        <mesh
          filename="meshes/pinky_proximal.STL" />
      </geometry>
    </collision>
  </link>
  <joint
    name="pinky_mcp_pitch"
    type="revolute">
    <origin
      xyz="0.0022097 0 0.015275"
      rpy="0 0 0" />
    <parent
      link="pinky_metacarpals" />
    <child
      link="pinky_proximal" />
    <axis
      xyz="0 1 0" />
    <limit
      lower="0"
      upper="1.36"
      effort="4.8"
      velocity="1" />
  </joint>
  <link
    name="pinky_middle">
    <inertial>
      <origin
        xyz="-0.00250309214140259 2.1894783039933E-06 0.0110397383273556"
        rpy="0 0 0" />
      <mass
        value="0.00283043906989622" />
      <inertia
        ixx="2.61037124783617E-07"
        ixy="5.7617222079153E-11"
        ixz="-4.00110565109454E-08"
        iyy="2.33077513229909E-07"
        iyz="-2.86988443315275E-11"
        izz="1.2654380297458E-07" />
    </inertial>
    <visual>
      <origin
        xyz="0 0 0"
        rpy="0 0 0" />
      <geometry>
        <mesh
          filename="meshes/pinky_middle.STL" />
      </geometry>
      <material
        name="">
        <color
          rgba="0.59 0.66 0.68 1" />
      </material>
    </visual>
    <collision>
      <origin
        xyz="0 0 0"
        rpy="0 0 0" />
      <geometry>
        <mesh
          filename="meshes/pinky_middle.STL" />
      </geometry>
    </collision>
  </link>
  <joint
    name="pinky_pip"
    type="revolute">
    <origin
      xyz="-0.0010697 0 0.035634"
      rpy="0 0 0" />
    <parent
      link="pinky_proximal" />
    <child
      link="pinky_middle" />
    <axis
      xyz="0 1 0" />
    <limit
      lower="0"
      upper="1.78"
      effort="3.7"
      velocity="1" />
    <mimic
      joint="pinky_mcp_pitch"
      multiplier="1.3"
      offset="0" />
  </joint>
  <link
    name="pinky_distal">
    <inertial>
      <origin
        xyz="-0.000604492895887754 -4.75263680191351E-06 0.0121511379180032"
        rpy="0 0 0" />
      <mass
        value="0.00314455887032079" />
      <inertia
        ixx="1.64071496633017E-07"
        ixy="1.95563986835622E-11"
        ixz="-4.27779200959899E-08"
        iyy="1.48363675410427E-07"
        iyz="-1.9679860568024E-10"
        izz="9.78043717695209E-08" />
    </inertial>
    <visual>
      <origin
        xyz="0 0 0"
        rpy="0 0 0" />
      <geometry>
        <mesh
          filename="meshes/pinky_distal.STL" />
      </geometry>
      <material
        name="">
        <color
          rgba="0.59 0.66 0.68 1" />
      </material>
    </visual>
    <collision>
      <origin
        xyz="0 0 0"
        rpy="0 0 0" />
      <geometry>
        <mesh
          filename="meshes/pinky_distal.STL" />
      </geometry>
    </collision>
  </link>
  <joint
    name="pinky_dip"
    type="revolute">
    <origin
      xyz="-0.0052444 0 0.025711"
      rpy="0 0 0" />
    <parent
      link="pinky_middle" />
    <child
      link="pinky_distal" />
    <axis
      xyz="0 1 0" />
    <limit
      lower="0"
      upper="0.62"
      effort="10.43"
      velocity="1" />
    <mimic
      joint="pinky_mcp_pitch"
      multiplier="0.46"
      offset="0" />
  </joint>
</robot>