<?xml version="1.0" encoding="utf-8"?>
<robot
  name="linkerhand_l10B_right.urdf">
  <link
    name="hand_base_link">
    <inertial>
      <origin
        xyz="-0.00378572993475002 -0.00041583904893102 0.083639288361369"
        rpy="0 0 0" />
      <mass
        value="0.108844276105116" />
      <inertia
        ixx="0.000193454839560416"
        ixy="-1.28842682703635E-06"
        ixz="-1.97005632027442E-07"
        iyy="0.000129793182936331"
        iyz="2.34961034039848E-06"
        izz="7.75126657491833E-05" />
    </inertial>
    <visual>
      <origin
        xyz="0 0 0"
        rpy="0 0 0" />
      <geometry>
        <mesh
          filename="meshes/hand_base_link.STL" />
      </geometry>
      <material
        name="">
        <color
          rgba="0.59 0.66 0.68 1" />
      </material>
    </visual>
    <collision>
      <origin
        xyz="0 0 0"
        rpy="0 0 0" />
      <geometry>
        <mesh
          filename="meshes/hand_base_link.STL" />
      </geometry>
    </collision>
  </link>
  <link
    name="thumb_metacarpals_base1">
    <inertial>
      <origin
        xyz="0.0284798868788809 -0.00318431295224701 1.02719477181115E-05"
        rpy="0 0 0" />
      <mass
        value="0.0084581547726202" />
      <inertia
        ixx="1.40243836130246E-06"
        ixy="-1.19619722062239E-07"
        ixz="7.34394052250468E-09"
        iyy="9.92829395244375E-07"
        iyz="4.64162077403213E-08"
        izz="7.26110349167423E-07" />
    </inertial>
    <visual>
      <origin
        xyz="0 0 0"
        rpy="0 0 0" />
      <geometry>
        <mesh
          filename="meshes/thumb_metacarpals_base1.STL" />
      </geometry>
      <material
        name="">
        <color
          rgba="0.59 0.66 0.68 1" />
      </material>
    </visual>
    <collision>
      <origin
        xyz="0 0 0"
        rpy="0 0 0" />
      <geometry>
        <mesh
          filename="meshes/thumb_metacarpals_base1.STL" />
      </geometry>
    </collision>
  </link>
  <joint
    name="thumb_cmc_roll"
    type="revolute">
    <origin
      xyz="-0.013419 0.012551 0.060602"
      rpy="0 0 0" />
    <parent
      link="hand_base_link" />
    <child
      link="thumb_metacarpals_base1" />
    <axis
      xyz="0.99996 0 -0.0087265" />
    <limit
      lower="0"
      upper="1.03"
      effort="4.8"
      velocity="1" />
  </joint>
  <link
    name="thumb_metacarpals_base2">
    <inertial>
      <origin
        xyz="0.00174090957798892 0.00721482590041489 -0.000263313052030728"
        rpy="0 0 0" />
      <mass
        value="0.00582711245702963" />
      <inertia
        ixx="3.17303010997568E-07"
        ixy="1.12913904502057E-08"
        ixz="-2.63903919763792E-09"
        iyy="2.73232268452871E-07"
        iyz="-1.09223121289568E-08"
        izz="1.76908306988949E-07" />
    </inertial>
    <visual>
      <origin
        xyz="0 0 0"
        rpy="0 0 0" />
      <geometry>
        <mesh
          filename="meshes/thumb_metacarpals_base2.STL" />
      </geometry>
      <material
        name="">
        <color
          rgba="0.59 0.66 0.68 1" />
      </material>
    </visual>
    <collision>
      <origin
        xyz="0 0 0"
        rpy="0 0 0" />
      <geometry>
        <mesh
          filename="meshes/thumb_metacarpals_base2.STL" />
      </geometry>
    </collision>
  </link>
  <joint
    name="thumb_cmc_yaw"
    type="revolute">
    <origin
      xyz="0.035798 -0.0006691 0.00040146"
      rpy="-0.13233 -0.0085747 0.0011413" />
    <parent
      link="thumb_metacarpals_base1" />
    <child
      link="thumb_metacarpals_base2" />
    <axis
      xyz="0 0 -1" />
    <limit
      lower="0"
      upper="1.40"
      effort="4.8"
      velocity="1" />
  </joint>
  <link
    name="thumb_metacarpals">
    <inertial>
      <origin
        xyz="0.00183662400665177 -2.80439600631663E-06 0.0269904280709441"
        rpy="0 0 0" />
      <mass
        value="0.0152012256765109" />
      <inertia
        ixx="2.95371260447027E-06"
        ixy="-6.21178551021653E-11"
        ixz="-1.58082424321764E-07"
        iyy="3.8477229500142E-06"
        iyz="-4.14758708520733E-10"
        izz="1.32007940012866E-06" />
    </inertial>
    <visual>
      <origin
        xyz="0 0 0"
        rpy="0 0 0" />
      <geometry>
        <mesh
          filename="meshes/thumb_metacarpals.STL" />
      </geometry>
      <material
        name="">
        <color
          rgba="0.59 0.66 0.68 1" />
      </material>
    </visual>
    <collision>
      <origin
        xyz="0 0 0"
        rpy="0 0 0" />
      <geometry>
        <mesh
          filename="meshes/thumb_metacarpals.STL" />
      </geometry>
    </collision>
  </link>
  <joint
    name="thumb_cmc_pitch"
    type="revolute">
    <origin
      xyz="0.0037151 0.015396 -0.0019302"
      rpy="0 -0.9163 -1.8076" />
    <parent
      link="thumb_metacarpals_base2" />
    <child
      link="thumb_metacarpals" />
    <axis
      xyz="0 1 0" />
    <limit
      lower="0"
      upper="0.52"
      effort="4.8"
      velocity="1" />
  </joint>
  <link
    name="thumb_proximal">
    <inertial>
      <origin
        xyz="0.00159268252983606 -4.43643671124011E-06 0.015157363827759"
        rpy="0 0 0" />
      <mass
        value="0.00662231923284161" />
      <inertia
        ixx="1.01527279135723E-06"
        ixy="3.86298144933713E-12"
        ixz="-4.42245334725163E-08"
        iyy="9.10434608488902E-07"
        iyz="-2.76864906314695E-11"
        izz="4.47464440479559E-07" />
    </inertial>
    <visual>
      <origin
        xyz="0 0 0"
        rpy="0 0 0" />
      <geometry>
        <mesh
          filename="meshes/thumb_proximal.STL" />
      </geometry>
      <material
        name="">
        <color
          rgba="0.59 0.66 0.68 1" />
      </material>
    </visual>
    <collision>
      <origin
        xyz="0 0 0"
        rpy="0 0 0" />
      <geometry>
        <mesh
          filename="meshes/thumb_proximal.STL" />
      </geometry>
    </collision>
  </link>
  <joint
    name="thumb_mcp"
    type="revolute">
    <origin
      xyz="0.0061722 0 0.047968"
      rpy="0 0 0" />
    <parent
      link="thumb_metacarpals" />
    <child
      link="thumb_proximal" />
    <axis
      xyz="0 1 0" />
    <limit
      lower="0"
      upper="0.72"
      effort="3.7"
      velocity="1" />
    <mimic
      joint="thumb_cmc_pitch"
      multiplier="1.38"
      offset="0" />
  </joint>
  <link
    name="thumb_distal">
    <inertial>
      <origin
        xyz="-0.00138929852568181 1.78258724357894E-06 0.0115789166085123"
        rpy="0 0 0" />
      <mass
        value="0.00512919991432349" />
      <inertia
        ixx="3.30966764284813E-07"
        ixy="3.4874903065333E-10"
        ixz="-1.0473713688836E-07"
        iyy="3.23803379547457E-07"
        iyz="8.38797000457644E-11"
        izz="2.48897458436709E-07" />
    </inertial>
    <visual>
      <origin
        xyz="0 0 0"
        rpy="0 0 0" />
      <geometry>
        <mesh
          filename="meshes/thumb_distal.STL" />
      </geometry>
      <material
        name="">
        <color
          rgba="0.59 0.66 0.68 1" />
      </material>
    </visual>
    <collision>
      <origin
        xyz="0 0 0"
        rpy="0 0 0" />
      <geometry>
        <mesh
          filename="meshes/thumb_distal.STL" />
      </geometry>
    </collision>
  </link>
  <joint
    name="thumb_ip"
    type="revolute">
    <origin
      xyz="-0.00017064 0 0.038665"
      rpy="0 0 0" />
    <parent
      link="thumb_proximal" />
    <child
      link="thumb_distal" />
    <axis
      xyz="0 1 0" />
    <limit
      lower="0"
      upper="0.78"
      effort="3.36"
      velocity="1" />
    <mimic
      joint="thumb_cmc_pitch"
      multiplier="1.49"
      offset="0" />
  </joint>
  <link
    name="index_metacarpals">
    <inertial>
      <origin
        xyz="-0.000394044300581899 -6.96524768268453E-07 0.00909446180986484"
        rpy="0 0 0" />
      <mass
        value="0.00903700329493157" />
      <inertia
        ixx="4.89554250283515E-07"
        ixy="-3.94697795521512E-11"
        ixz="2.73097237930781E-08"
        iyy="7.37380385682221E-07"
        iyz="-6.33508384593073E-11"
        izz="5.52862732336676E-07" />
    </inertial>
    <visual>
      <origin
        xyz="0 0 0"
        rpy="0 0 0" />
      <geometry>
        <mesh
          filename="meshes/index_metacarpals.STL" />
      </geometry>
      <material
        name="">
        <color
          rgba="0.59 0.66 0.68 1" />
      </material>
    </visual>
    <collision>
      <origin
        xyz="0 0 0"
        rpy="0 0 0" />
      <geometry>
        <mesh
          filename="meshes/index_metacarpals.STL" />
      </geometry>
    </collision>
  </link>
  <joint
    name="index_mcp_roll"
    type="revolute">
    <origin
      xyz="-0.0021643 0.026654 0.13253"
      rpy="-0.027925 -0.0087266 0" />
    <parent
      link="hand_base_link" />
    <child
      link="index_metacarpals" />
    <axis
      xyz="-1 0 0" />
    <limit
      lower="0"
      upper="0.19"
      effort="100"
      velocity="1" />
  </joint>
  <link
    name="index_proximal">
    <inertial>
      <origin
        xyz="-0.000129944380960653 1.17196171642124E-06 0.0104816955547003"
        rpy="0 0 0" />
      <mass
        value="0.00654982235507964" />
      <inertia
        ixx="4.43901400960209E-07"
        ixy="3.44400810155697E-12"
        ixz="-2.4814971446792E-08"
        iyy="4.58697731369085E-07"
        iyz="8.51406115918214E-11"
        izz="1.74205815221237E-07" />
    </inertial>
    <visual>
      <origin
        xyz="0 0 0"
        rpy="0 0 0" />
      <geometry>
        <mesh
          filename="meshes/index_proximal.STL" />
      </geometry>
      <material
        name="">
        <color
          rgba="0.59 0.66 0.68 1" />
      </material>
    </visual>
    <collision>
      <origin
        xyz="0 0 0"
        rpy="0 0 0" />
      <geometry>
        <mesh
          filename="meshes/index_proximal.STL" />
      </geometry>
    </collision>
  </link>
  <joint
    name="index_mcp_pitch"
    type="revolute">
    <origin
      xyz="0.00220968332188026 0 0.0152749792820048"
      rpy="0 0 0" />
    <parent
      link="index_metacarpals" />
    <child
      link="index_proximal" />
    <axis
      xyz="0 1 0" />
    <limit
      lower="0"
      upper="1.36"
      effort="4.8"
      velocity="1" />
  </joint>
  <link
    name="index_middle">
    <inertial>
      <origin
        xyz="-0.00250308175256513 -2.09528008505294E-06 0.0110397399346051"
        rpy="0 0 0" />
      <mass
        value="0.00283043630937165" />
      <inertia
        ixx="2.61037002532157E-07"
        ixy="-5.76553826316728E-11"
        ixz="-4.00111847827091E-08"
        iyy="2.33077671005604E-07"
        iyz="2.97012055424732E-11"
        izz="1.2654386429984E-07" />
    </inertial>
    <visual>
      <origin
        xyz="0 0 0"
        rpy="0 0 0" />
      <geometry>
        <mesh
          filename="meshes/index_middle.STL" />
      </geometry>
      <material
        name="">
        <color
          rgba="0.59 0.66 0.68 1" />
      </material>
    </visual>
    <collision>
      <origin
        xyz="0 0 0"
        rpy="0 0 0" />
      <geometry>
        <mesh
          filename="meshes/index_middle.STL" />
      </geometry>
    </collision>
  </link>
  <joint
    name="index_pip"
    type="revolute">
    <origin
      xyz="-0.0010697 0 0.035634"
      rpy="0 0 0" />
    <parent
      link="index_proximal" />
    <child
      link="index_middle" />
    <axis
      xyz="0 1 0" />
    <limit
      lower="0"
      upper="1.78"
      effort="3.7"
      velocity="1" />
    <mimic
      joint="index_mcp_pitch"
      multiplier="1.3"
      offset="0" />
  </joint>
  <link
    name="index_distal">
    <inertial>
      <origin
        xyz="-0.000604588906740394 5.26099433146611E-06 0.0121514585299274"
        rpy="0 0 0" />
      <mass
        value="0.0031446130611452" />
      <inertia
        ixx="1.64075846532352E-07"
        ixy="-1.75219464852339E-11"
        ixz="-4.27797730478817E-08"
        iyy="1.48367877966466E-07"
        iyz="2.03355501606508E-10"
        izz="9.78063887942514E-08" />
    </inertial>
    <visual>
      <origin
        xyz="0 0 0"
        rpy="0 0 0" />
      <geometry>
        <mesh
          filename="meshes/index_distal.STL" />
      </geometry>
      <material
        name="">
        <color
          rgba="0.59 0.66 0.68 1" />
      </material>
    </visual>
    <collision>
      <origin
        xyz="0 0 0"
        rpy="0 0 0" />
      <geometry>
        <mesh
          filename="meshes/index_distal.STL" />
      </geometry>
    </collision>
  </link>
  <joint
    name="index_dip"
    type="revolute">
    <origin
      xyz="-0.0052444 0 0.025711"
      rpy="0 0 0" />
    <parent
      link="index_middle" />
    <child
      link="index_distal" />
    <axis
      xyz="0 1 0" />
    <limit
      lower="0"
      upper="0.62"
      effort="10.43"
      velocity="1" />
    <mimic
      joint="index_mcp_pitch"
      multiplier="0.46"
      offset="0" />
  </joint>
  <link
    name="middle_proximal">
    <inertial>
      <origin
        xyz="-0.000226219980586554 1.17216483217029E-06 0.0104800581470382"
        rpy="0 0 0" />
      <mass
        value="0.00654982478226949" />
      <inertia
        ixx="4.43422823045882E-07"
        ixy="2.65801609334198E-12"
        ixz="-2.72879331079685E-08"
        iyy="4.58697754707373E-07"
        iyz="8.52654749038393E-11"
        izz="1.746844667607E-07" />
    </inertial>
    <visual>
      <origin
        xyz="0 0 0"
        rpy="0 0 0" />
      <geometry>
        <mesh
          filename="meshes/middle_proximal.STL" />
      </geometry>
      <material
        name="">
        <color
          rgba="0.59 0.66 0.68 1" />
      </material>
    </visual>
    <collision>
      <origin
        xyz="0 0 0"
        rpy="0 0 0" />
      <geometry>
        <mesh
          filename="meshes/middle_proximal.STL" />
      </geometry>
    </collision>
  </link>
  <joint
    name="middle_mcp_pitch"
    type="revolute">
    <origin
      xyz="-0.00213155528434806 0.00765417737818821 0.152810108410232"
      rpy="0 0 0" />
    <parent
      link="hand_base_link" />
    <child
      link="middle_proximal" />
    <axis
      xyz="0 1 0" />
    <limit
      lower="0"
      upper="1.36"
      effort="100"
      velocity="1" />
  </joint>
  <link
    name="middle_middle">
    <inertial>
      <origin
        xyz="-0.00261699473119731 -2.09526685194996E-06 0.0110132928110042"
        rpy="0 0 0" />
      <mass
        value="0.00283043635504842" />
      <inertia
        ixx="2.60196021834948E-07"
        ixy="-5.79547865424222E-11"
        ixz="-4.13919583593881E-08"
        iyy="2.33077669434872E-07"
        iyz="2.9104841260857E-11"
        izz="1.27384845266404E-07" />
    </inertial>
    <visual>
      <origin
        xyz="0 0 0"
        rpy="0 0 0" />
      <geometry>
        <mesh
          filename="meshes/middle_middle.STL" />
      </geometry>
      <material
        name="">
        <color
          rgba="0.59 0.66 0.68 1" />
      </material>
    </visual>
    <collision>
      <origin
        xyz="0 0 0"
        rpy="0 0 0" />
      <geometry>
        <mesh
          filename="meshes/middle_middle.STL" />
      </geometry>
    </collision>
  </link>
  <joint
    name="middle_pip"
    type="revolute">
    <origin
      xyz="-0.00139702428111229 0 0.0356230829860553"
      rpy="0 0 0" />
    <parent
      link="middle_proximal" />
    <child
      link="middle_middle" />
    <axis
      xyz="0 1 0" />
    <limit
      lower="0"
      upper="1.78"
      effort="3.7"
      velocity="1" />
    <mimic
      joint="middle_mcp_pitch"
      multiplier="1.3"
      offset="0" />
  </joint>
  <link
    name="middle_distal">
    <inertial>
      <origin
        xyz="-0.000728492686371173 5.23463092580619E-06 0.0121446078355885"
        rpy="0 0 0" />
      <mass
        value="0.00314458659113992" />
      <inertia
        ixx="1.63194300204967E-07"
        ixy="-1.99064062210326E-11"
        ixz="-4.34469141576056E-08"
        iyy="1.48366133401819E-07"
        iyz="2.02741720954809E-10"
        izz="9.8685363448972E-08" />
    </inertial>
    <visual>
      <origin
        xyz="0 0 0"
        rpy="0 0 0" />
      <geometry>
        <mesh
          filename="meshes/middle_distal.STL" />
      </geometry>
      <material
        name="">
        <color
          rgba="0.59 0.66 0.68 1" />
      </material>
    </visual>
    <collision>
      <origin
        xyz="0 0 0"
        rpy="0 0 0" />
      <geometry>
        <mesh
          filename="meshes/middle_distal.STL" />
      </geometry>
    </collision>
  </link>
  <joint
    name="middle_dip"
    type="revolute">
    <origin
      xyz="-0.0055098 0 0.025656"
      rpy="0 0 0" />
    <parent
      link="middle_middle" />
    <child
      link="middle_distal" />
    <axis
      xyz="0 1 0" />
    <limit
      lower="0"
      upper="0.62"
      effort="10.43"
      velocity="1" />
    <mimic
      joint="middle_mcp_pitch"
      multiplier="0.46"
      offset="0" />
  </joint>
  <link
    name="ring_metacarpals">
    <inertial>
      <origin
        xyz="-0.000394044453752051 -6.96464269499264E-07 0.00909446164305169"
        rpy="0 0 0" />
      <mass
        value="0.00903700335356623" />
      <inertia
        ixx="4.89554245950771E-07"
        ixy="-3.94741777907138E-11"
        ixz="2.73097253166787E-08"
        iyy="7.37380377611045E-07"
        iyz="-6.33493307330511E-11"
        izz="5.52862742016819E-07" />
    </inertial>
    <visual>
      <origin
        xyz="0 0 0"
        rpy="0 0 0" />
      <geometry>
        <mesh
          filename="meshes/ring_metacarpals.STL" />
      </geometry>
      <material
        name="">
        <color
          rgba="0.59 0.66 0.68 1" />
      </material>
    </visual>
    <collision>
      <origin
        xyz="0 0 0"
        rpy="0 0 0" />
      <geometry>
        <mesh
          filename="meshes/ring_metacarpals.STL" />
      </geometry>
    </collision>
  </link>
  <joint
    name="ring_mcp_roll"
    type="revolute">
    <origin
      xyz="-0.00216430029569533 -0.0113458226218121 0.132534071328313"
      rpy="0.0244346095279086 -0.00872664625996829 0" />
    <parent
      link="hand_base_link" />
    <child
      link="ring_metacarpals" />
    <axis
      xyz="1 0 0" />
    <limit
      lower="0"
      upper="0.2"
      effort="4.29"
      velocity="1" />
  </joint>
  <link
    name="ring_proximal">
    <inertial>
      <origin
        xyz="-0.000129951741702268 1.17052693794986E-06 0.0104816759358435"
        rpy="0 0 0" />
      <mass
        value="0.00654983629670871" />
      <inertia
        ixx="4.43901586303392E-07"
        ixy="3.50295306689535E-12"
        ixz="-2.48148215954452E-08"
        iyy="4.58698142287549E-07"
        iyz="8.52333703161162E-11"
        izz="1.74206152792307E-07" />
    </inertial>
    <visual>
      <origin
        xyz="0 0 0"
        rpy="0 0 0" />
      <geometry>
        <mesh
          filename="meshes/ring_proximal.STL" />
      </geometry>
      <material
        name="">
        <color
          rgba="0.59 0.66 0.68 1" />
      </material>
    </visual>
    <collision>
      <origin
        xyz="0 0 0"
        rpy="0 0 0" />
      <geometry>
        <mesh
          filename="meshes/ring_proximal.STL" />
      </geometry>
    </collision>
  </link>
  <joint
    name="ring_mcp_pitch"
    type="revolute">
    <origin
      xyz="0.0022097 0 0.015275"
      rpy="0 0 0" />
    <parent
      link="ring_metacarpals" />
    <child
      link="ring_proximal" />
    <axis
      xyz="0 1 0" />
    <limit
      lower="0"
      upper="1.36"
      effort="4.8"
      velocity="1" />
  </joint>
  <link
    name="ring_middle">
    <inertial>
      <origin
        xyz="-0.00250308200880736 -2.09549542964232E-06 0.0110397403443072"
        rpy="0 0 0" />
      <mass
        value="0.0028304363455826" />
      <inertia
        ixx="2.610370084214E-07"
        ixy="-5.76575489930258E-11"
        ixz="-4.00111860002357E-08"
        iyy="2.3307766580208E-07"
        iyz="2.97027542466601E-11"
        izz="1.26543852008426E-07" />
    </inertial>
    <visual>
      <origin
        xyz="0 0 0"
        rpy="0 0 0" />
      <geometry>
        <mesh
          filename="meshes/ring_middle.STL" />
      </geometry>
      <material
        name="">
        <color
          rgba="0.59 0.66 0.68 1" />
      </material>
    </visual>
    <collision>
      <origin
        xyz="0 0 0"
        rpy="0 0 0" />
      <geometry>
        <mesh
          filename="meshes/ring_middle.STL" />
      </geometry>
    </collision>
  </link>
  <joint
    name="ring_pip"
    type="revolute">
    <origin
      xyz="-0.00106974956301328 0 0.0356344124989653"
      rpy="0 0 0" />
    <parent
      link="ring_proximal" />
    <child
      link="ring_middle" />
    <axis
      xyz="0 1 0" />
    <limit
      lower="0"
      upper="1.78"
      effort="3.7"
      velocity="1" />
    <mimic
      joint="ring_mcp_pitch"
      multiplier="1.34"
      offset="0" />
  </joint>
  <link
    name="ring_distal">
    <inertial>
      <origin
        xyz="-0.00060459286126547 5.09148089232817E-06 0.0121514427640609"
        rpy="0 0 0" />
      <mass
        value="0.00314460631735109" />
      <inertia
        ixx="1.64075455538032E-07"
        ixy="-2.1468512857682E-11"
        ixz="-4.27798116117893E-08"
        iyy="1.48367698956355E-07"
        iyz="1.93419127705868E-10"
        izz="9.78062648939272E-08" />
    </inertial>
    <visual>
      <origin
        xyz="0 0 0"
        rpy="0 0 0" />
      <geometry>
        <mesh
          filename="meshes/ring_distal.STL" />
      </geometry>
      <material
        name="">
        <color
          rgba="0.59 0.66 0.68 1" />
      </material>
    </visual>
    <collision>
      <origin
        xyz="0 0 0"
        rpy="0 0 0" />
      <geometry>
        <mesh
          filename="meshes/ring_distal.STL" />
      </geometry>
    </collision>
  </link>
  <joint
    name="ring_dip"
    type="revolute">
    <origin
      xyz="-0.00524443259686075 0 0.0257114125710868"
      rpy="0 0 -0.000213216385347256" />
    <parent
      link="ring_middle" />
    <child
      link="ring_distal" />
    <axis
      xyz="0.000213099161087669 0.999450193223668 -0.033155178387707" />
    <limit
      lower="0"
      upper="0.62"
      effort="10.43"
      velocity="1" />
    <mimic
      joint="ring_mcp_pitch"
      multiplier="0.46"
      offset="0" />
  </joint>
  <link
    name="pinky_metacarpals">
    <inertial>
      <origin
        xyz="-0.00039404522692532 -6.96240700731598E-07 0.00909446058676422"
        rpy="0 0 0" />
      <mass
        value="0.00903700307878998" />
      <inertia
        ixx="4.89554195779539E-07"
        ixy="-3.94817181132792E-11"
        ixz="2.7309708213456E-08"
        iyy="7.37380317460272E-07"
        iyz="-6.33317017267926E-11"
        izz="5.5286276236961E-07" />
    </inertial>
    <visual>
      <origin
        xyz="0 0 0"
        rpy="0 0 0" />
      <geometry>
        <mesh
          filename="meshes/pinky_metacarpals.STL" />
      </geometry>
      <material
        name="">
        <color
          rgba="0.59 0.66 0.68 1" />
      </material>
    </visual>
    <collision>
      <origin
        xyz="0 0 0"
        rpy="0 0 0" />
      <geometry>
        <mesh
          filename="meshes/pinky_metacarpals.STL" />
      </geometry>
    </collision>
  </link>
  <joint
    name="pinky_mcp_roll"
    type="revolute">
    <origin
      xyz="-0.00012074 -0.030346 0.12755"
      rpy="0.057596 -0.0087266 0" />
    <parent
      link="hand_base_link" />
    <child
      link="pinky_metacarpals" />
    <axis
      xyz="1 0 0" />
    <limit
      lower="0"
      upper="0.3"
      effort="4.29"
      velocity="1" />
  </joint>
  <link
    name="pinky_proximal">
    <inertial>
      <origin
        xyz="-0.000129949532354408 1.17230680928004E-06 0.0104816807512055"
        rpy="0 0 0" />
      <mass
        value="0.00654983474179372" />
      <inertia
        ixx="4.43901730245286E-07"
        ixy="3.4507527836803E-12"
        ixz="-2.48149152090791E-08"
        iyy="4.58698159687316E-07"
        iyz="8.52432689792127E-11"
        izz="1.74206088330646E-07" />
    </inertial>
    <visual>
      <origin
        xyz="0 0 0"
        rpy="0 0 0" />
      <geometry>
        <mesh
          filename="meshes/pinky_proximal.STL" />
      </geometry>
      <material
        name="">
        <color
          rgba="0.59 0.66 0.68 1" />
      </material>
    </visual>
    <collision>
      <origin
        xyz="0 0 0"
        rpy="0 0 0" />
      <geometry>
        <mesh
          filename="meshes/pinky_proximal.STL" />
      </geometry>
    </collision>
  </link>
  <joint
    name="pinky_mcp_pitch"
    type="revolute">
    <origin
      xyz="0.0022097 0 0.015275"
      rpy="0 0 0" />
    <parent
      link="pinky_metacarpals" />
    <child
      link="pinky_proximal" />
    <axis
      xyz="0 1 0" />
    <limit
      lower="0"
      upper="1.36"
      effort="4.8"
      velocity="1" />
  </joint>
  <link
    name="pinky_middle">
    <inertial>
      <origin
        xyz="-0.00250308414609457 -2.09612030866585E-06 0.0110397422037874"
        rpy="0 0 0" />
      <mass
        value="0.00283043670305552" />
      <inertia
        ixx="2.6103697292473E-07"
        ixy="-5.76245409160896E-11"
        ixz="-4.00111424508735E-08"
        iyy="2.33077589871973E-07"
        iyz="2.96769001441938E-11"
        izz="1.26543829688383E-07" />
    </inertial>
    <visual>
      <origin
        xyz="0 0 0"
        rpy="0 0 0" />
      <geometry>
        <mesh
          filename="meshes/pinky_middle.STL" />
      </geometry>
      <material
        name="">
        <color
          rgba="0.59 0.66 0.68 1" />
      </material>
    </visual>
    <collision>
      <origin
        xyz="0 0 0"
        rpy="0 0 0" />
      <geometry>
        <mesh
          filename="meshes/pinky_middle.STL" />
      </geometry>
    </collision>
  </link>
  <joint
    name="pinky_pip"
    type="revolute">
    <origin
      xyz="-0.0010697 0 0.035634"
      rpy="0 0 0" />
    <parent
      link="pinky_proximal" />
    <child
      link="pinky_middle" />
    <axis
      xyz="0 1 0" />
    <limit
      lower="0"
      upper="1.78"
      effort="3.7"
      velocity="1" />
    <mimic
      joint="pinky_mcp_pitch"
      multiplier="1.34"
      offset="0" />
  </joint>
  <link
    name="pinky_distal">
    <inertial>
      <origin
        xyz="-0.000604482988543969 5.27153358490656E-06 0.0121512430050648"
        rpy="0 0 0" />
      <mass
        value="0.00314457409502053" />
      <inertia
        ixx="1.64068754964363E-07"
        ixy="-1.90437996173564E-11"
        ixz="-4.27789862984836E-08"
        iyy="1.48361079085349E-07"
        iyz="2.05110113267167E-10"
        izz="9.78068531228973E-08" />
    </inertial>
    <visual>
      <origin
        xyz="0 0 0"
        rpy="0 0 0" />
      <geometry>
        <mesh
          filename="meshes/pinky_distal.STL" />
      </geometry>
      <material
        name="">
        <color
          rgba="0.59 0.66 0.68 1" />
      </material>
    </visual>
    <collision>
      <origin
        xyz="0 0 0"
        rpy="0 0 0" />
      <geometry>
        <mesh
          filename="meshes/pinky_distal.STL" />
      </geometry>
    </collision>
  </link>
  <joint
    name="pinky_dip"
    type="revolute">
    <origin
      xyz="-0.0052444 0 0.025711"
      rpy="0 0 0" />
    <parent
      link="pinky_middle" />
    <child
      link="pinky_distal" />
   <axis
      xyz="0 1 0" />
    <limit
      lower="0"
      upper="0.62"
      effort="10.43"
      velocity="1" />
    <mimic
      joint="pinky_mcp_pitch"
      multiplier="0.46"
      offset="0" />
  </joint>
</robot>